Workbook

Sheet Prensa
A1: MODIFICADO | H1: ORIGINAL
A2: prensa31 | B2: BOOL | C2: 0.00 | D2: Prensa 31 | E2: 0 | F2: =IF(C2="","",IF(OR(COUNTIF($C:$C,C2)>1,COUNTIF(Prensa!C:C,C2)+COUNTIF(Carga!C:C,C2)+COUNTIF(Escolha41!C:C,C2)+COUNTIF(Escolha43!C:C,C2)-COUNTIF($C:$C,C2)>0),"CONFLITO","OK")) -> OK | H2: anoRelogio | I2: CHANNEL | J2: D210 | K2: Ano Relógio | L2: 0
A3: prensa30 | B3: BOOL | C3: 0.01 | D3: Prensa 30 | E3: 0 | F3: =IF(C3="","",IF(OR(COUNTIF($C:$C,C3)>1,COUNTIF(Prensa!C:C,C3)+COUNTIF(Carga!C:C,C3)+COUNTIF(Escolha41!C:C,C3)+COUNTIF(Escolha43!C:C,C3)-COUNTIF($C:$C,C3)>0),"CONFLITO","OK")) -> OK | H3: relogio4dig | I3: CHANNEL | J3: D211 | K3: Ano Relógio 4 digitos | L3: 0
A4: prensa29 | B4: BOOL | C4: 0.02 | D4: Prensa 29 | E4: 0 | F4: =IF(C4="","",IF(OR(COUNTIF($C:$C,C4)>1,COUNTIF(Prensa!C:C,C4)+COUNTIF(Carga!C:C,C4)+COUNTIF(Escolha41!C:C,C4)+COUNTIF(Escolha43!C:C,C4)-COUNTIF($C:$C,C4)>0),"CONFLITO","OK")) -> OK | H4: PH29paradaT1 | I4: CHANNEL | J4: D1 | K4: cnt prensa 31 parada T1 | L4: 0
A5: ph29parada | B5: BOOL | C5: 10.00 | D5: prensa 29 parada | E5: 0 | F5: =IF(C5="","",IF(OR(COUNTIF($C:$C,C5)>1,COUNTIF(Prensa!C:C,C5)+COUNTIF(Carga!C:C,C5)+COUNTIF(Escolha41!C:C,C5)+COUNTIF(Escolha43!C:C,C5)-COUNTIF($C:$C,C5)>0),"CONFLITO","OK")) -> OK | H5: PH30paradaT1 | I5: CHANNEL | J5: D2 | K5: cnt prensa 31 parada T1 | L5: 0
A6: ph30parada | B6: BOOL | C6: 10.01 | D6: prensa 30 parada | E6: 0 | F6: =IF(C6="","",IF(OR(COUNTIF($C:$C,C6)>1,COUNTIF(Prensa!C:C,C6)+COUNTIF(Carga!C:C,C6)+COUNTIF(Escolha41!C:C,C6)+COUNTIF(Escolha43!C:C,C6)-COUNTIF($C:$C,C6)>0),"CONFLITO","OK")) -> OK | H6: PH31paradaT1 | I6: CHANNEL | J6: D3 | K6: cnt prensa 31 parada T1 | L6: 0
A7: ph31parada | B7: BOOL | C7: 10.03 | D7: prensa 31 parada | E7: 0 | F7: =IF(C7="","",IF(OR(COUNTIF($C:$C,C7)>1,COUNTIF(Prensa!C:C,C7)+COUNTIF(Carga!C:C,C7)+COUNTIF(Escolha41!C:C,C7)+COUNTIF(Escolha43!C:C,C7)-COUNTIF($C:$C,C7)>0),"CONFLITO","OK")) -> OK | H7: PH29paradaT2 | I7: CHANNEL | J7: D4 | K7: cnt prensa 31 parada T2 | L7: 0
A8: KEEP | B8: BOOL | C8: 10.04 | E8: 0 | F8: =IF(C8="","",IF(OR(COUNTIF($C:$C,C8)>1,COUNTIF(Prensa!C:C,C8)+COUNTIF(Carga!C:C,C8)+COUNTIF(Escolha41!C:C,C8)+COUNTIF(Escolha43!C:C,C8)-COUNTIF($C:$C,C8)>0),"CONFLITO","OK")) -> OK | H8: PH30paradaT2 | I8: CHANNEL | J8: D5 | K8: cnt prensa 31 parada T2 | L8: 0
A9: PH29paradaT1 | B9: CHANNEL | C9: D0 | D9: cnt prensa 31 parada T1 | E9: 0 | F9: =IF(C9="","",IF(OR(COUNTIF($C:$C,C9)>1,COUNTIF(Prensa!C:C,C9)+COUNTIF(Carga!C:C,C9)+COUNTIF(Escolha41!C:C,C9)+COUNTIF(Escolha43!C:C,C9)-COUNTIF($C:$C,C9)>0),"CONFLITO","OK")) -> OK | H9: PH31paradaT2 | I9: CHANNEL | J9: D6 | K9: cnt prensa 31 parada T2 | L9: 0
A10: PH31paradaT2 | B10: CHANNEL | C10: D10 | D10: cnt prensa 31 parada T2 | E10: 0 | F10: =IF(C10="","",IF(OR(COUNTIF($C:$C,C10)>1,COUNTIF(Prensa!C:C,C10)+COUNTIF(Carga!C:C,C10)+COUNTIF(Escolha41!C:C,C10)+COUNTIF(Escolha43!C:C,C10)-COUNTIF($C:$C,C10)>0),"CONFLITO","OK")) -> OK | H10: PH29paradaT3 | I10: CHANNEL | J10: D7 | K10: cnt prensa 31 parada T3 | L10: 0
A11: PH29paradaT3 | B11: CHANNEL | C11: D12 | D11: cnt prensa 31 parada T3 | E11: 0 | F11: =IF(C11="","",IF(OR(COUNTIF($C:$C,C11)>1,COUNTIF(Prensa!C:C,C11)+COUNTIF(Carga!C:C,C11)+COUNTIF(Escolha41!C:C,C11)+COUNTIF(Escolha43!C:C,C11)-COUNTIF($C:$C,C11)>0),"CONFLITO","OK")) -> OK | H11: PH30paradaT3 | I11: CHANNEL | J11: D8 | K11: cnt prensa 31 parada T3 | L11: 0
A12: PH30paradaT3 | B12: CHANNEL | C12: D14 | D12: cnt prensa 31 parada T3 | E12: 0 | F12: =IF(C12="","",IF(OR(COUNTIF($C:$C,C12)>1,COUNTIF(Prensa!C:C,C12)+COUNTIF(Carga!C:C,C12)+COUNTIF(Escolha41!C:C,C12)+COUNTIF(Escolha43!C:C,C12)-COUNTIF($C:$C,C12)>0),"CONFLITO","OK")) -> OK | H12: PH31paradaT3 | I12: CHANNEL | J12: D9 | K12: cnt prensa 31 parada T3 | L12: 0
A13: PH31paradaT3 | B13: CHANNEL | C13: D18 | D13: cnt prensa 31 parada T3 | E13: 0 | F13: =IF(C13="","",IF(OR(COUNTIF($C:$C,C13)>1,COUNTIF(Prensa!C:C,C13)+COUNTIF(Carga!C:C,C13)+COUNTIF(Escolha41!C:C,C13)+COUNTIF(Escolha43!C:C,C13)-COUNTIF($C:$C,C13)>0),"CONFLITO","OK")) -> OK | H13: codFormPH29 | I13: CHANNEL | J13: D409 | K13: Codigo do formato ph29 | L13: 0
A14: PH30paradaT1 | B14: CHANNEL | C14: D2 | D14: cnt prensa 31 parada T1 | E14: 0 | F14: =IF(C14="","",IF(OR(COUNTIF($C:$C,C14)>1,COUNTIF(Prensa!C:C,C14)+COUNTIF(Carga!C:C,C14)+COUNTIF(Escolha41!C:C,C14)+COUNTIF(Escolha43!C:C,C14)-COUNTIF($C:$C,C14)>0),"CONFLITO","OK")) -> OK | H14: codFormPH30 | I14: CHANNEL | J14: D407 | K14: Codigo do formato ph30 | L14: 0
A15: pecaPH29 | B15: CHANNEL | C15: D20 | D15: conta peças ph29 | E15: 0 | F15: =IF(C15="","",IF(OR(COUNTIF($C:$C,C15)>1,COUNTIF(Prensa!C:C,C15)+COUNTIF(Carga!C:C,C15)+COUNTIF(Escolha41!C:C,C15)+COUNTIF(Escolha43!C:C,C15)-COUNTIF($C:$C,C15)>0),"CONFLITO","OK")) -> OK | H15: codFormPH31 | I15: CHANNEL | J15: D405 | K15: Codigo do formato ph31 | L15: 0
A16: pecaPH30 | B16: CHANNEL | C16: D22 | D16: conta peças ph30 | E16: 0 | F16: =IF(C16="","",IF(OR(COUNTIF($C:$C,C16)>1,COUNTIF(Prensa!C:C,C16)+COUNTIF(Carga!C:C,C16)+COUNTIF(Escolha41!C:C,C16)+COUNTIF(Escolha43!C:C,C16)-COUNTIF($C:$C,C16)>0),"CONFLITO","OK")) -> OK | H16: pecaPH29 | I16: CHANNEL | J16: D100 | K16: conta peças ph29 | L16: 0
A17: pecaPH31 | B17: CHANNEL | C17: D24 | D17: conta peças ph31 | E17: 0 | F17: =IF(C17="","",IF(OR(COUNTIF($C:$C,C17)>1,COUNTIF(Prensa!C:C,C17)+COUNTIF(Carga!C:C,C17)+COUNTIF(Escolha41!C:C,C17)+COUNTIF(Escolha43!C:C,C17)-COUNTIF($C:$C,C17)>0),"CONFLITO","OK")) -> OK | H17: pecaPH30 | I17: CHANNEL | J17: D102 | K17: conta peças ph30 | L17: 0
A18: segundosRelogio | B18: CHANNEL | C18: D26 | D18: Segundos Relógio | E18: 0 | F18: =IF(C18="","",IF(OR(COUNTIF($C:$C,C18)>1,COUNTIF(Prensa!C:C,C18)+COUNTIF(Carga!C:C,C18)+COUNTIF(Escolha41!C:C,C18)+COUNTIF(Escolha43!C:C,C18)-COUNTIF($C:$C,C18)>0),"CONFLITO","OK")) -> OK | H18: pecaPH31 | I18: CHANNEL | J18: D104 | K18: conta peças ph31 | L18: 0
A19: minutosRelogio | B19: CHANNEL | C19: D28 | D19: Minutos Relógio | E19: 0 | F19: =IF(C19="","",IF(OR(COUNTIF($C:$C,C19)>1,COUNTIF(Prensa!C:C,C19)+COUNTIF(Carga!C:C,C19)+COUNTIF(Escolha41!C:C,C19)+COUNTIF(Escolha43!C:C,C19)-COUNTIF($C:$C,C19)>0),"CONFLITO","OK")) -> OK | H19: diaCalendario | I19: CHANNEL | J19: D806 | K19: dia calendario | L19: 0
A20: horaRelogio | B20: CHANNEL | C20: D30 | D20: Horas Relogio | E20: 0 | F20: =IF(C20="","",IF(OR(COUNTIF($C:$C,C20)>1,COUNTIF(Prensa!C:C,C20)+COUNTIF(Carga!C:C,C20)+COUNTIF(Escolha41!C:C,C20)+COUNTIF(Escolha43!C:C,C20)-COUNTIF($C:$C,C20)>0),"CONFLITO","OK")) -> OK | H20: diaMes | I20: CHANNEL | J20: D400 | K20: dia do mes | L20: 0
... A31: codFormPH30 | B31: CHANNEL | C31: D50 | D31: Codigo do formato ph30 | E31: 0 | F31: =IF(C31="","",IF(OR(COUNTIF($C:$C,C31)>1,COUNTIF(Prensa!C:C,C31)+COUNTIF(Carga!C:C,C31)+COUNTIF(Escolha41!C:C,C31)+COUNTIF(Escolha43!C:C,C31)-COUNTIF($C:$C,C31)>0),"CONFLITO","OK")) -> OK | H31: MemAtuaReloSupervisorio | I31: BOOL | J31: H20.00 | K31: Memória Atualiza Relogio pelo supervisório | L31: 0
A32: _31dias_vezes_2_ph31 | B32: WORD | C32: D500 | E32: 0 | F32: =IF(C32="","",IF(OR(COUNTIF($C:$C,C32)>1,COUNTIF(Prensa!C:C,C32)+COUNTIF(Carga!C:C,C32)+COUNTIF(Escolha41!C:C,C32)+COUNTIF(Escolha43!C:C,C32)-COUNTIF($C:$C,C32)>0),"CONFLITO","OK")) -> OK | H32: mesCalendario | I32: CHANNEL | J32: D808 | K32: mes calendario | L32: 0
A33: Ponteiro_Dword_ph31 | B33: WORD | C33: D502 | E33: 0 | F33: =IF(C33="","",IF(OR(COUNTIF($C:$C,C33)>1,COUNTIF(Prensa!C:C,C33)+COUNTIF(Carga!C:C,C33)+COUNTIF(Escolha41!C:C,C33)+COUNTIF(Escolha43!C:C,C33)-COUNTIF($C:$C,C33)>0),"CONFLITO","OK")) -> OK | H33: mesRelogio | I33: CHANNEL | J33: D209 | K33: Mes Relogio | L33: 0
A34: Memória_de_Armazenagem_ph31 | B34: WORD | C34: D504 | E34: 0 | F34: =IF(C34="","",IF(OR(COUNTIF($C:$C,C34)>1,COUNTIF(Prensa!C:C,C34)+COUNTIF(Carga!C:C,C34)+COUNTIF(Escolha41!C:C,C34)+COUNTIF(Escolha43!C:C,C34)-COUNTIF($C:$C,C34)>0),"CONFLITO","OK")) -> OK | H34: mesSelecionado | I34: CHANNEL | J34: D810 | K34: mês selecionado | L34: 0
A35: Memoria_contagem_BIN_ph31 | B35: WORD | C35: D506 | E35: 0 | F35: =IF(C35="","",IF(OR(COUNTIF($C:$C,C35)>1,COUNTIF(Prensa!C:C,C35)+COUNTIF(Carga!C:C,C35)+COUNTIF(Escolha41!C:C,C35)+COUNTIF(Escolha43!C:C,C35)-COUNTIF($C:$C,C35)>0),"CONFLITO","OK")) -> OK | H35: mesSelect | I35: CHANNEL | J35: D910 | K35: mês selecionado | L35: 0
A36: ponteiroBDph31 | B36: WORD | C36: D508 | D36: ponteiro banco de dados PH31 | E36: 0 | F36: =IF(C36="","",IF(OR(COUNTIF($C:$C,C36)>1,COUNTIF(Prensa!C:C,C36)+COUNTIF(Carga!C:C,C36)+COUNTIF(Escolha41!C:C,C36)+COUNTIF(Escolha43!C:C,C36)-COUNTIF($C:$C,C36)>0),"CONFLITO","OK")) -> CONFLITO | H36: minutos | I36: CHANNEL | J36: D802 | K36: minutos | L36: 0
A37: Memoria_contagem_BCD_ph31 | B37: WORD | C37: D508 | E37: 0 | F37: =IF(C37="","",IF(OR(COUNTIF($C:$C,C37)>1,COUNTIF(Prensa!C:C,C37)+COUNTIF(Carga!C:C,C37)+COUNTIF(Escolha41!C:C,C37)+COUNTIF(Escolha43!C:C,C37)-COUNTIF($C:$C,C37)>0),"CONFLITO","OK")) -> CONFLITO | H37: minutosRelogio | I37: CHANNEL | J37: D206 | K37: Minutos Relógio | L37: 0
A38: _31dias_vezes_2_ph30 | B38: WORD | C38: D510 | F38: =IF(C38="","",IF(OR(COUNTIF($C:$C,C38)>1,COUNTIF(Prensa!C:C,C38)+COUNTIF(Carga!C:C,C38)+COUNTIF(Escolha41!C:C,C38)+COUNTIF(Escolha43!C:C,C38)-COUNTIF($C:$C,C38)>0),"CONFLITO","OK")) -> OK | H38: numberCavidPH29 | I38: CHANNEL | J38: D408 | K38: Número cavidades na prensa29 | L38: 0
A39: Ponteiro_Dword_ph30 | B39: WORD | C39: D512 | F39: =IF(C39="","",IF(OR(COUNTIF($C:$C,C39)>1,COUNTIF(Prensa!C:C,C39)+COUNTIF(Carga!C:C,C39)+COUNTIF(Escolha41!C:C,C39)+COUNTIF(Escolha43!C:C,C39)-COUNTIF($C:$C,C39)>0),"CONFLITO","OK")) -> OK | H39: numberCavidPH30 | I39: CHANNEL | J39: D406 | K39: Número cavidades na prensa30 | L39: 0
A40: Memória_de_Armazenagem_ph30 | B40: WORD | C40: D514 | F40: =IF(C40="","",IF(OR(COUNTIF($C:$C,C40)>1,COUNTIF(Prensa!C:C,C40)+COUNTIF(Carga!C:C,C40)+COUNTIF(Escolha41!C:C,C40)+COUNTIF(Escolha43!C:C,C40)-COUNTIF($C:$C,C40)>0),"CONFLITO","OK")) -> OK | H40: numberCavidPH31 | I40: CHANNEL | J40: D404 | K40: Número cavidades na prensa31 | L40: 0
A41: Memoria_contagem_BIN_ph30 | B41: WORD | C41: D516 | F41: =IF(C41="","",IF(OR(COUNTIF($C:$C,C41)>1,COUNTIF(Prensa!C:C,C41)+COUNTIF(Carga!C:C,C41)+COUNTIF(Escolha41!C:C,C41)+COUNTIF(Escolha43!C:C,C41)-COUNTIF($C:$C,C41)>0),"CONFLITO","OK")) -> OK | H41: firstDMenvioPcPH | I41: CHANNEL | J41: D402 | K41: pirmeiro DM de envio peças ph | L41: 0
A42: ponteiroBDph30 | B42: CHANNEL | C42: D518 | D42: ponteiro em BCD para armazenar a contagem | E42: 0 | F42: =IF(C42="","",IF(OR(COUNTIF($C:$C,C42)>1,COUNTIF(Prensa!C:C,C42)+COUNTIF(Carga!C:C,C42)+COUNTIF(Escolha41!C:C,C42)+COUNTIF(Escolha43!C:C,C42)-COUNTIF($C:$C,C42)>0),"CONFLITO","OK")) -> CONFLITO | H42: ponteiroBDph29 | I42: WORD | J42: D528 | K42: ponteiro banco de dados PH 29 | L42: 0
A43: Memoria_contagem_BCD_ph30 | B43: WORD | C43: D518 | F43: =IF(C43="","",IF(OR(COUNTIF($C:$C,C43)>1,COUNTIF(Prensa!C:C,C43)+COUNTIF(Carga!C:C,C43)+COUNTIF(Escolha41!C:C,C43)+COUNTIF(Escolha43!C:C,C43)-COUNTIF($C:$C,C43)>0),"CONFLITO","OK")) -> CONFLITO | H43: ponteiroBDph31 | I43: WORD | J43: D508 | K43: ponteiro banco de dados PH31 | L43: 0
A44: numberCavidPH29 | B44: CHANNEL | C44: D52 | D44: Número cavidades na prensa29 | E44: 0 | F44: =IF(C44="","",IF(OR(COUNTIF($C:$C,C44)>1,COUNTIF(Prensa!C:C,C44)+COUNTIF(Carga!C:C,C44)+COUNTIF(Escolha41!C:C,C44)+COUNTIF(Escolha43!C:C,C44)-COUNTIF($C:$C,C44)>0),"CONFLITO","OK")) -> OK | H44: ponteiroBDph30 | I44: CHANNEL | J44: D518 | K44: ponteiro em BCD para armazenar a contagem | L44: 0
A45: _31dias_vezes_2_ph29 | B45: WORD | C45: D520 | F45: =IF(C45="","",IF(OR(COUNTIF($C:$C,C45)>1,COUNTIF(Prensa!C:C,C45)+COUNTIF(Carga!C:C,C45)+COUNTIF(Escolha41!C:C,C45)+COUNTIF(Escolha43!C:C,C45)-COUNTIF($C:$C,C45)>0),"CONFLITO","OK")) -> OK | H45: prensa29 | I45: BOOL | J45: 0.02 | K45: Prensa 29 | L45: 0
A46: Ponteiro_Dword_ph29 | B46: WORD | C46: D522 | F46: =IF(C46="","",IF(OR(COUNTIF($C:$C,C46)>1,COUNTIF(Prensa!C:C,C46)+COUNTIF(Carga!C:C,C46)+COUNTIF(Escolha41!C:C,C46)+COUNTIF(Escolha43!C:C,C46)-COUNTIF($C:$C,C46)>0),"CONFLITO","OK")) -> OK | H46: ph29parada | I46: BOOL | J46: 20.00 | K46: prensa 29 parada | L46: 0
A47: Memória_de_Armazenagem_ph29 | B47: WORD | C47: D524 | F47: =IF(C47="","",IF(OR(COUNTIF($C:$C,C47)>1,COUNTIF(Prensa!C:C,C47)+COUNTIF(Carga!C:C,C47)+COUNTIF(Escolha41!C:C,C47)+COUNTIF(Escolha43!C:C,C47)-COUNTIF($C:$C,C47)>0),"CONFLITO","OK")) -> OK | H47: prensa30 | I47: BOOL | J47: 0.01 | K47: Prensa 30 | L47: 0
A48: Memoria_contagem_BIN_ph29 | B48: WORD | C48: D526 | F48: =IF(C48="","",IF(OR(COUNTIF($C:$C,C48)>1,COUNTIF(Prensa!C:C,C48)+COUNTIF(Carga!C:C,C48)+COUNTIF(Escolha41!C:C,C48)+COUNTIF(Escolha43!C:C,C48)-COUNTIF($C:$C,C48)>0),"CONFLITO","OK")) -> OK | H48: ph30parada | I48: BOOL | J48: 21.00 | K48: prensa 30 parada | L48: 0
A49: ponteiroBDph29 | B49: WORD | C49: D528 | D49: ponteiro banco de dados PH 29 | E49: 0 | F49: =IF(C49="","",IF(OR(COUNTIF($C:$C,C49)>1,COUNTIF(Prensa!C:C,C49)+COUNTIF(Carga!C:C,C49)+COUNTIF(Escolha41!C:C,C49)+COUNTIF(Escolha43!C:C,C49)-COUNTIF($C:$C,C49)>0),"CONFLITO","OK")) -> CONFLITO | H49: prensa31 | I49: BOOL | J49: 0.00 | K49: Prensa 31 | L49: 0
A50: Memoria_contagem_BCD_ph29 | B50: WORD | C50: D528 | F50: =IF(C50="","",IF(OR(COUNTIF($C:$C,C50)>1,COUNTIF(Prensa!C:C,C50)+COUNTIF(Carga!C:C,C50)+COUNTIF(Escolha41!C:C,C50)+COUNTIF(Escolha43!C:C,C50)-COUNTIF($C:$C,C50)>0),"CONFLITO","OK")) -> CONFLITO | H50: ph31parada | I50: BOOL | J50: 22.00 | K50: prensa 31 parada | L50: 0
...

Sheet Carga
A1: _d_segundos | B1: CHANNEL | C1: D150 | D1: segundos | E1: 0 | F1: =IF(C1="","",IF(OR(COUNTIF($C:$C,C1)>1,COUNTIF(Prensa!C:C,C1)+COUNTIF(Carga!C:C,C1)+COUNTIF(Escolha41!C:C,C1)+COUNTIF(Escolha43!C:C,C1)-COUNTIF($C:$C,C1)>0),"CONFLITO","OK")) -> OK | I1: ORIGINAL
A2: _r_horas | B2: CHANNEL | C2: D151 | D2: horas | E2: 0 | F2: =IF(C2="","",IF(OR(COUNTIF($C:$C,C2)>1,COUNTIF(Prensa!C:C,C2)+COUNTIF(Carga!C:C,C2)+COUNTIF(Escolha41!C:C,C2)+COUNTIF(Escolha43!C:C,C2)-COUNTIF($C:$C,C2)>0),"CONFLITO","OK")) -> OK | G2: ponteiroDB22 | H2: CHANNEL | I2: D518 | K2: 0
A3: _t_minutos | B3: CHANNEL | C3: D152 | D3: minutos | E3: 0 | F3: =IF(C3="","",IF(OR(COUNTIF($C:$C,C3)>1,COUNTIF(Prensa!C:C,C3)+COUNTIF(Carga!C:C,C3)+COUNTIF(Escolha41!C:C,C3)+COUNTIF(Escolha43!C:C,C3)-COUNTIF($C:$C,C3)>0),"CONFLITO","OK")) -> OK | G3: anoRelogio_ | H3: CHANNEL | I3: D210 | J3: Ano Relogio | K3: 0
A4: anoRelogio | B4: CHANNEL | C4: D153 | D4: Ano Relógio | E4: 0 | F4: =IF(C4="","",IF(OR(COUNTIF($C:$C,C4)>1,COUNTIF(Prensa!C:C,C4)+COUNTIF(Carga!C:C,C4)+COUNTIF(Escolha41!C:C,C4)+COUNTIF(Escolha43!C:C,C4)-COUNTIF($C:$C,C4)>0),"CONFLITO","OK")) -> OK | G4: anoRelogio | H4: CHANNEL | I4: D300 | J4: Ano Relógio | K4: 0
A5: anoRelogio_ | B5: CHANNEL | C5: D154 | D5: Ano Relógio | E5: 0 | F5: =IF(C5="","",IF(OR(COUNTIF($C:$C,C5)>1,COUNTIF(Prensa!C:C,C5)+COUNTIF(Carga!C:C,C5)+COUNTIF(Escolha41!C:C,C5)+COUNTIF(Escolha43!C:C,C5)-COUNTIF($C:$C,C5)>0),"CONFLITO","OK")) -> OK | G5: AnoRelogio4dig_ | H5: CHANNEL | I5: D211 | J5: Ano Relogio 4 Digitos | K5: 0
A6: AnoRelogio4dig_ | B6: CHANNEL | C6: D155 | D6: Ano Relogio 4 Digitos | E6: 0 | F6: =IF(C6="","",IF(OR(COUNTIF($C:$C,C6)>1,COUNTIF(Prensa!C:C,C6)+COUNTIF(Carga!C:C,C6)+COUNTIF(Escolha41!C:C,C6)+COUNTIF(Escolha43!C:C,C6)-COUNTIF($C:$C,C6)>0),"CONFLITO","OK")) -> OK | G6: AnoRelógio4dit | H6: CHANNEL | I6: D301 | J6: Ano Relógio 4 digitos | K6: 0
A7: AnoRelógio4dit | B7: CHANNEL | C7: D156 | D7: Ano Relógio 4 digitos | E7: 0 | F7: =IF(C7="","",IF(OR(COUNTIF($C:$C,C7)>1,COUNTIF(Prensa!C:C,C7)+COUNTIF(Carga!C:C,C7)+COUNTIF(Escolha41!C:C,C7)+COUNTIF(Escolha43!C:C,C7)-COUNTIF($C:$C,C7)>0),"CONFLITO","OK")) -> OK | G7: bancBaixoF18 | H7: BOOL | I7: 0.06 | J7: bancalino baixo carga forno 18 | K7: 0
A8: bancBaixoF18 | B8: BOOL | C8: 40.06 | D8: bancalino baixo carga forno 18 | E8: 0 | F8: =IF(C8="","",IF(OR(COUNTIF($C:$C,C8)>1,COUNTIF(Prensa!C:C,C8)+COUNTIF(Carga!C:C,C8)+COUNTIF(Escolha41!C:C,C8)+COUNTIF(Escolha43!C:C,C8)-COUNTIF($C:$C,C8)>0),"CONFLITO","OK")) -> OK | G8: bancEntradaForno22 | H8: BOOL | I8: 0.10 | J8: bancalino entrada forno | K8: 0
A9: bancEntradaForno22 | B9: BOOL | C9: 40.10 | D9: bancalino entrada forno | E9: 0 | F9: =IF(C9="","",IF(OR(COUNTIF($C:$C,C9)>1,COUNTIF(Prensa!C:C,C9)+COUNTIF(Carga!C:C,C9)+COUNTIF(Escolha41!C:C,C9)+COUNTIF(Escolha43!C:C,C9)-COUNTIF($C:$C,C9)>0),"CONFLITO","OK")) -> OK | G9: cntPlanosRollerCarga43 | H9: BOOL | I9: 0.08 | J9: cnt de planos de carga 43 | K9: 0
A10: cntContPc | B10: CHANNEL | C10: D157 | D10: contador peças | E10: 0 | F10: =IF(C10="","",IF(OR(COUNTIF($C:$C,C10)>1,COUNTIF(Prensa!C:C,C10)+COUNTIF(Carga!C:C,C10)+COUNTIF(Escolha41!C:C,C10)+COUNTIF(Escolha43!C:C,C10)-COUNTIF($C:$C,C10)>0),"CONFLITO","OK")) -> OK | G10: cntPlanosRollerDescarga43 | H10: BOOL | I10: 0.09 | J10: cnt de planos de descarga 43 | K10: 0
A11: cntPlanos43 | B11: CHANNEL | C11: C43 | D11: contador de planos da 43 | E11: 0 | F11: =IF(C11="","",IF(OR(COUNTIF($C:$C,C11)>1,COUNTIF(Prensa!C:C,C11)+COUNTIF(Carga!C:C,C11)+COUNTIF(Escolha41!C:C,C11)+COUNTIF(Escolha43!C:C,C11)-COUNTIF($C:$C,C11)>0),"CONFLITO","OK")) -> OK | G11: estoqueVazio43 | H11: BOOL | I11: 30.05 | J11: comparador planos vazios | K11: 0
A12: cntPlanosCargaRoller41 | B12: BOOL | C12: 41.00 | D12: contagem de planos da carga carro | E12: 0 | F12: =IF(C12="","",IF(OR(COUNTIF($C:$C,C12)>1,COUNTIF(Prensa!C:C,C12)+COUNTIF(Carga!C:C,C12)+COUNTIF(Escolha41!C:C,C12)+COUNTIF(Escolha43!C:C,C12)-COUNTIF($C:$C,C12)>0),"CONFLITO","OK")) -> OK | G12: cntPlanosCargaRoller42 | H12: BOOL | I12: 1.02 | J12: contador de gavetas carga roller mf42 | K12: 0
A13: cntPlanosCargaRoller42 | B13: BOOL | C13: 41.02 | D13: contador de gavetas carga roller mf42 | E13: 0 | F13: =IF(C13="","",IF(OR(COUNTIF($C:$C,C13)>1,COUNTIF(Prensa!C:C,C13)+COUNTIF(Carga!C:C,C13)+COUNTIF(Escolha41!C:C,C13)+COUNTIF(Escolha43!C:C,C13)-COUNTIF($C:$C,C13)>0),"CONFLITO","OK")) -> OK | G13: cntPlanos43 | H13: CHANNEL | I13: C43 | J13: contador de planos da 43 | K13: 0
A14: cntPlanosDescRolle41 | B14: BOOL | C14: 41.05 | D14: contagem de planos da descarga carro | E14: 0 | F14: =IF(C14="","",IF(OR(COUNTIF($C:$C,C14)>1,COUNTIF(Prensa!C:C,C14)+COUNTIF(Carga!C:C,C14)+COUNTIF(Escolha41!C:C,C14)+COUNTIF(Escolha43!C:C,C14)-COUNTIF($C:$C,C14)>0),"CONFLITO","OK")) -> OK | G14: cntPlanosRollerDescarga42 | H14: BOOL | I14: 1.04 | J14: contador descarga gaveta roller descarga mf42 | K14: 0
... A70: peçaPorF22 | B70: CHANNEL | C70: D173 | D70: peças por fila f22 | E70: 0 | F70: =IF(C70="","",IF(OR(COUNTIF($C:$C,C70)>1,COUNTIF(Prensa!C:C,C70)+COUNTIF(Carga!C:C,C70)+COUNTIF(Escolha41!C:C,C70)+COUNTIF(Escolha43!C:C,C70)-COUNTIF($C:$C,C70)>0),"CONFLITO","OK")) -> OK | G70: resetCnt11 | H70: BOOL | I70: 50.03 | J70: reset cnt11 | K70: 0
A71: ponteiroDB22 | B71: CHANNEL | C71: D174 | E71: 0 | F71: =IF(C71="","",IF(OR(COUNTIF($C:$C,C71)>1,COUNTIF(Prensa!C:C,C71)+COUNTIF(Carga!C:C,C71)+COUNTIF(Escolha41!C:C,C71)+COUNTIF(Escolha43!C:C,C71)-COUNTIF($C:$C,C71)>0),"CONFLITO","OK")) -> OK | G71: resetCnt12 | H71: BOOL | I71: 50.05 | J71: reset cnt12 | K71: 0
A72: receitaDestF22 | B72: CHANNEL | C72: D3800 | D72: receita de destino F22 | E72: 0 | F72: =IF(C72="","",IF(OR(COUNTIF($C:$C,C72)>1,COUNTIF(Prensa!C:C,C72)+COUNTIF(Carga!C:C,C72)+COUNTIF(Escolha41!C:C,C72)+COUNTIF(Escolha43!C:C,C72)-COUNTIF($C:$C,C72)>0),"CONFLITO","OK")) -> OK | G72: resetInicioT1 | H72: BOOL | I72: C0010 | J72: reset inicio turno 1 | K72: 0
A73: receitaDestRolle43 | B73: CHANNEL | C73: D3001 | D73: receita de destino RC43 | E73: 0 | F73: =IF(C73="","",IF(OR(COUNTIF($C:$C,C73)>1,COUNTIF(Prensa!C:C,C73)+COUNTIF(Carga!C:C,C73)+COUNTIF(Escolha41!C:C,C73)+COUNTIF(Escolha43!C:C,C73)-COUNTIF($C:$C,C73)>0),"CONFLITO","OK")) -> OK | G73: resetInicioT2 | H73: BOOL | I73: C0011 | J73: reset inicio turno 2 | K73: 0
A74: releF18 | B74: BOOL | C74: 40.07 | D74: rele forno 18 (saida 3.03) | E74: 0 | F74: =IF(C74="","",IF(OR(COUNTIF($C:$C,C74)>1,COUNTIF(Prensa!C:C,C74)+COUNTIF(Carga!C:C,C74)+COUNTIF(Escolha41!C:C,C74)+COUNTIF(Escolha43!C:C,C74)-COUNTIF($C:$C,C74)>0),"CONFLITO","OK")) -> OK | G74: resetInicioT3 | H74: BOOL | I74: C0012 | J74: reset inicio turno 3 | K74: 0
A75: releF22 | B75: BOOL | C75: 40.11 | D75: rele forno 22 | E75: 0 | F75: =IF(C75="","",IF(OR(COUNTIF($C:$C,C75)>1,COUNTIF(Prensa!C:C,C75)+COUNTIF(Carga!C:C,C75)+COUNTIF(Escolha41!C:C,C75)+COUNTIF(Escolha43!C:C,C75)-COUNTIF($C:$C,C75)>0),"CONFLITO","OK")) -> OK | G75: reseRetornoPc1 | H75: BOOL | I75: 20.00 | J75: reset retorno peças | K75: 0
A76: reseRetornoPc1 | B76: BOOL | C76: 20.00 | D76: reset retorno peças | E76: 0 | F76: =IF(C76="","",IF(OR(COUNTIF($C:$C,C76)>1,COUNTIF(Prensa!C:C,C76)+COUNTIF(Carga!C:C,C76)+COUNTIF(Escolha41!C:C,C76)+COUNTIF(Escolha43!C:C,C76)-COUNTIF($C:$C,C76)>0),"CONFLITO","OK")) -> OK | G76: reseRetornoPc2 | H76: BOOL | I76: 20.01 | J76: reset retorno peças | K76: 0
A77: reseRetornoPc2 | B77: BOOL | C77: 20.01 | D77: reset retorno peças | E77: 0 | F77: =IF(C77="","",IF(OR(COUNTIF($C:$C,C77)>1,COUNTIF(Prensa!C:C,C77)+COUNTIF(Carga!C:C,C77)+COUNTIF(Escolha41!C:C,C77)+COUNTIF(Escolha43!C:C,C77)-COUNTIF($C:$C,C77)>0),"CONFLITO","OK")) -> OK | G77: reseRetornoPc3 | H77: BOOL | I77: 20.02 | J77: reset retorno peças | K77: 0
A78: reseRetornoPc3 | B78: BOOL | C78: 20.02 | D78: reset retorno peças | E78: 0 | F78: =IF(C78="","",IF(OR(COUNTIF($C:$C,C78)>1,COUNTIF(Prensa!C:C,C78)+COUNTIF(Carga!C:C,C78)+COUNTIF(Escolha41!C:C,C78)+COUNTIF(Escolha43!C:C,C78)-COUNTIF($C:$C,C78)>0),"CONFLITO","OK")) -> OK | G78: HrollerC42 | H78: BOOL | I78: H10.03 | J78: roller carga 42 | K78: 0
A79: resetCnt10 | B79: BOOL | C79: 50.01 | D79: reset cnt10 | E79: 0 | F79: =IF(C79="","",IF(OR(COUNTIF($C:$C,C79)>1,COUNTIF(Prensa!C:C,C79)+COUNTIF(Carga!C:C,C79)+COUNTIF(Escolha41!C:C,C79)+COUNTIF(Escolha43!C:C,C79)-COUNTIF($C:$C,C79)>0),"CONFLITO","OK")) -> OK | G79: HrollerCarg43 | H79: BOOL | I79: H10.07 | J79: roller carga 43 | K79: 0
A80: resetCnt11 | B80: BOOL | C80: 50.03 | D80: reset cnt11 | E80: 0 | F80: =IF(C80="","",IF(OR(COUNTIF($C:$C,C80)>1,COUNTIF(Prensa!C:C,C80)+COUNTIF(Carga!C:C,C80)+COUNTIF(Escolha41!C:C,C80)+COUNTIF(Escolha43!C:C,C80)-COUNTIF($C:$C,C80)>0),"CONFLITO","OK")) -> OK | G80: HrollerDesc41 | H80: BOOL | I80: H10.06 | J80: roller descarga 41 | K80: 0
A81: resetCnt12 | B81: BOOL | C81: 50.05 | D81: reset cnt12 | E81: 0 | F81: =IF(C81="","",IF(OR(COUNTIF($C:$C,C81)>1,COUNTIF(Prensa!C:C,C81)+COUNTIF(Carga!C:C,C81)+COUNTIF(Escolha41!C:C,C81)+COUNTIF(Escolha43!C:C,C81)-COUNTIF($C:$C,C81)>0),"CONFLITO","OK")) -> OK | G81: _d_segundos | H81: CHANNEL | I81: D804 | J81: segundos | K81: 0
A82: resetInicioT1 | B82: BOOL | C82: C0010 | D82: reset inicio turno 1 | E82: 0 | F82: =IF(C82="","",IF(OR(COUNTIF($C:$C,C82)>1,COUNTIF(Prensa!C:C,C82)+COUNTIF(Carga!C:C,C82)+COUNTIF(Escolha41!C:C,C82)+COUNTIF(Escolha43!C:C,C82)-COUNTIF($C:$C,C82)>0),"CONFLITO","OK")) -> OK | G82: segRelogio | H82: CHANNEL | I82: D205 | J82: Segundos Relógio | K82: 0
A83: resetInicioT2 | B83: BOOL | C83: C0011 | D83: reset inicio turno 2 | E83: 0 | F83: =IF(C83="","",IF(OR(COUNTIF($C:$C,C83)>1,COUNTIF(Prensa!C:C,C83)+COUNTIF(Carga!C:C,C83)+COUNTIF(Escolha41!C:C,C83)+COUNTIF(Escolha43!C:C,C83)-COUNTIF($C:$C,C83)>0),"CONFLITO","OK")) -> OK | G83: pcRollerDesc41 | H83: BOOL | I83: 0.01 | J83: sensor peças maquineta descarga 41 | K83: 0
... A92: turno1_2_3 | B92: CHANNEL | C92: D175 | D92: turno 1,2,3 | E92: 0 | F92: =IF(C92="","",IF(OR(COUNTIF($C:$C,C92)>1,COUNTIF(Prensa!C:C,C92)+COUNTIF(Carga!C:C,C92)+COUNTIF(Escolha41!C:C,C92)+COUNTIF(Escolha43!C:C,C92)-COUNTIF($C:$C,C92)>0),"CONFLITO","OK")) -> OK | G92: statusRollDesc43 | H92: BOOL | I92: H10.08 | J92: status roller descarga 43 | K92: 0
G93: turno1_2_3 | H93: CHANNEL | I93: D500 | J93: turno 1,2,3 | K93: 0

Sheet Escolha41
A1: bit2 | B1: BOOL | E1: 0
A2: d400D400 | B2: CHANNEL | C2: 0 | E2: 0 | F2: =IF(C2="","",IF(OR(COUNTIF($C:$C,C2)>1,COUNTIF(Prensa!C:C,C2)+COUNTIF(Carga!C:C,C2)+COUNTIF(Escolha41!C:C,C2)+COUNTIF(Escolha43!C:C,C2)-COUNTIF($C:$C,C2)>0),"CONFLITO","OK")) -> OK
A3: caco | B3: BOOL | C3: 4.00 | D3: caco | E3: 0 | F3: =IF(C3="","",IF(OR(COUNTIF($C:$C,C3)>1,COUNTIF(Prensa!C:C,C3)+COUNTIF(Carga!C:C,C3)+COUNTIF(Escolha41!C:C,C3)+COUNTIF(Escolha43!C:C,C3)-COUNTIF($C:$C,C3)>0),"CONFLITO","OK")) -> OK
A4: box1 | B4: BOOL | C4: 4.01 | D4: box1 | E4: 0 | F4: =IF(C4="","",IF(OR(COUNTIF($C:$C,C4)>1,COUNTIF(Prensa!C:C,C4)+COUNTIF(Carga!C:C,C4)+COUNTIF(Escolha41!C:C,C4)+COUNTIF(Escolha43!C:C,C4)-COUNTIF($C:$C,C4)>0),"CONFLITO","OK")) -> OK
A5: box2 | B5: BOOL | C5: 4.02 | D5: box2 | E5: 0 | F5: =IF(C5="","",IF(OR(COUNTIF($C:$C,C5)>1,COUNTIF(Prensa!C:C,C5)+COUNTIF(Carga!C:C,C5)+COUNTIF(Escolha41!C:C,C5)+COUNTIF(Escolha43!C:C,C5)-COUNTIF($C:$C,C5)>0),"CONFLITO","OK")) -> OK
A6: box3 | B6: BOOL | C6: 4.03 | D6: box3 | E6: 0 | F6: =IF(C6="","",IF(OR(COUNTIF($C:$C,C6)>1,COUNTIF(Prensa!C:C,C6)+COUNTIF(Carga!C:C,C6)+COUNTIF(Escolha41!C:C,C6)+COUNTIF(Escolha43!C:C,C6)-COUNTIF($C:$C,C6)>0),"CONFLITO","OK")) -> OK
A7: box4 | B7: BOOL | C7: 4.04 | D7: box4 | E7: 0 | F7: =IF(C7="","",IF(OR(COUNTIF($C:$C,C7)>1,COUNTIF(Prensa!C:C,C7)+COUNTIF(Carga!C:C,C7)+COUNTIF(Escolha41!C:C,C7)+COUNTIF(Escolha43!C:C,C7)-COUNTIF($C:$C,C7)>0),"CONFLITO","OK")) -> OK
A8: box5 | B8: BOOL | C8: 4.05 | D8: box5 | E8: 0 | F8: =IF(C8="","",IF(OR(COUNTIF($C:$C,C8)>1,COUNTIF(Prensa!C:C,C8)+COUNTIF(Carga!C:C,C8)+COUNTIF(Escolha41!C:C,C8)+COUNTIF(Escolha43!C:C,C8)-COUNTIF($C:$C,C8)>0),"CONFLITO","OK")) -> OK
A9: box6 | B9: BOOL | C9: 4.06 | D9: box6 | E9: 0 | F9: =IF(C9="","",IF(OR(COUNTIF($C:$C,C9)>1,COUNTIF(Prensa!C:C,C9)+COUNTIF(Carga!C:C,C9)+COUNTIF(Escolha41!C:C,C9)+COUNTIF(Escolha43!C:C,C9)-COUNTIF($C:$C,C9)>0),"CONFLITO","OK")) -> OK
A10: resetCnt | B10: BOOL | C10: 4.07 | D10: reset contagem | E10: 0 | F10: =IF(C10="","",IF(OR(COUNTIF($C:$C,C10)>1,COUNTIF(Prensa!C:C,C10)+COUNTIF(Carga!C:C,C10)+COUNTIF(Escolha41!C:C,C10)+COUNTIF(Escolha43!C:C,C10)-COUNTIF($C:$C,C10)>0),"CONFLITO","OK")) -> OK
A11: totalPc | B11: BOOL | C11: 4.08 | D11: total peças | E11: 0 | F11: =IF(C11="","",IF(OR(COUNTIF($C:$C,C11)>1,COUNTIF(Prensa!C:C,C11)+COUNTIF(Carga!C:C,C11)+COUNTIF(Escolha41!C:C,C11)+COUNTIF(Escolha43!C:C,C11)-COUNTIF($C:$C,C11)>0),"CONFLITO","OK")) -> OK
A12: selecaoCom | B12: BOOL | C12: 4.09 | D12: seleção comercial | E12: 0 | F12: =IF(C12="","",IF(OR(COUNTIF($C:$C,C12)>1,COUNTIF(Prensa!C:C,C12)+COUNTIF(Carga!C:C,C12)+COUNTIF(Escolha41!C:C,C12)+COUNTIF(Escolha43!C:C,C12)-COUNTIF($C:$C,C12)>0),"CONFLITO","OK")) -> OK
A13: TIM | B13: BOOL | C13: 4.12 | E13: 0 | F13: =IF(C13="","",IF(OR(COUNTIF($C:$C,C13)>1,COUNTIF(Prensa!C:C,C13)+COUNTIF(Carga!C:C,C13)+COUNTIF(Escolha41!C:C,C13)+COUNTIF(Escolha43!C:C,C13)-COUNTIF($C:$C,C13)>0),"CONFLITO","OK")) -> OK
A14: cntBox0 | B14: CHANNEL | C14: D300 | D14: contagem box 0 | E14: 0 | F14: =IF(C14="","",IF(OR(COUNTIF($C:$C,C14)>1,COUNTIF(Prensa!C:C,C14)+COUNTIF(Carga!C:C,C14)+COUNTIF(Escolha41!C:C,C14)+COUNTIF(Escolha43!C:C,C14)-COUNTIF($C:$C,C14)>0),"CONFLITO","OK")) -> OK
A15: cntBox1 | B15: CHANNEL | C15: D302 | D15: contagem box 1 | E15: 0 | F15: =IF(C15="","",IF(OR(COUNTIF($C:$C,C15)>1,COUNTIF(Prensa!C:C,C15)+COUNTIF(Carga!C:C,C15)+COUNTIF(Escolha41!C:C,C15)+COUNTIF(Escolha43!C:C,C15)-COUNTIF($C:$C,C15)>0),"CONFLITO","OK")) -> OK
A16: cntBox2 | B16: CHANNEL | C16: D304 | D16: contagem box 2 | E16: 0 | F16: =IF(C16="","",IF(OR(COUNTIF($C:$C,C16)>1,COUNTIF(Prensa!C:C,C16)+COUNTIF(Carga!C:C,C16)+COUNTIF(Escolha41!C:C,C16)+COUNTIF(Escolha43!C:C,C16)-COUNTIF($C:$C,C16)>0),"CONFLITO","OK")) -> OK
A17: cntBox3 | B17: CHANNEL | C17: D306 | D17: contagem box 3 | E17: 0 | F17: =IF(C17="","",IF(OR(COUNTIF($C:$C,C17)>1,COUNTIF(Prensa!C:C,C17)+COUNTIF(Carga!C:C,C17)+COUNTIF(Escolha41!C:C,C17)+COUNTIF(Escolha43!C:C,C17)-COUNTIF($C:$C,C17)>0),"CONFLITO","OK")) -> OK
A18: cntBox4 | B18: CHANNEL | C18: D308 | D18: contagem box 4 | E18: 0 | F18: =IF(C18="","",IF(OR(COUNTIF($C:$C,C18)>1,COUNTIF(Prensa!C:C,C18)+COUNTIF(Carga!C:C,C18)+COUNTIF(Escolha41!C:C,C18)+COUNTIF(Escolha43!C:C,C18)-COUNTIF($C:$C,C18)>0),"CONFLITO","OK")) -> OK
A19: cntBox5 | B19: CHANNEL | C19: D310 | D19: contagem box 5 | E19: 0 | F19: =IF(C19="","",IF(OR(COUNTIF($C:$C,C19)>1,COUNTIF(Prensa!C:C,C19)+COUNTIF(Carga!C:C,C19)+COUNTIF(Escolha41!C:C,C19)+COUNTIF(Escolha43!C:C,C19)-COUNTIF($C:$C,C19)>0),"CONFLITO","OK")) -> OK
A20: cntBox6 | B20: CHANNEL | C20: D312 | D20: contagem box 6 | E20: 0 | F20: =IF(C20="","",IF(OR(COUNTIF($C:$C,C20)>1,COUNTIF(Prensa!C:C,C20)+COUNTIF(Carga!C:C,C20)+COUNTIF(Escolha41!C:C,C20)+COUNTIF(Escolha43!C:C,C20)-COUNTIF($C:$C,C20)>0),"CONFLITO","OK")) -> OK
A21: cntTotal | B21: CHANNEL | C21: D314 | D21: contagem total | E21: 0 | F21: =IF(C21="","",IF(OR(COUNTIF($C:$C,C21)>1,COUNTIF(Prensa!C:C,C21)+COUNTIF(Carga!C:C,C21)+COUNTIF(Escolha41!C:C,C21)+COUNTIF(Escolha43!C:C,C21)-COUNTIF($C:$C,C21)>0),"CONFLITO","OK")) -> OK
A22: cntAmostragem | B22: CHANNEL | C22: D316 | D22: contador amostragem | E22: 0 | F22: =IF(C22="","",IF(OR(COUNTIF($C:$C,C22)>1,COUNTIF(Prensa!C:C,C22)+COUNTIF(Carga!C:C,C22)+COUNTIF(Escolha41!C:C,C22)+COUNTIF(Escolha43!C:C,C22)-COUNTIF($C:$C,C22)>0),"CONFLITO","OK")) -> OK
A23: segRelogio | B23: CHANNEL | C23: D318 | D23: Segundos Relógio | E23: 0 | F23: =IF(C23="","",IF(OR(COUNTIF($C:$C,C23)>1,COUNTIF(Prensa!C:C,C23)+COUNTIF(Carga!C:C,C23)+COUNTIF(Escolha41!C:C,C23)+COUNTIF(Escolha43!C:C,C23)-COUNTIF($C:$C,C23)>0),"CONFLITO","OK")) -> OK
A24: minRelogio | B24: CHANNEL | C24: D320 | D24: Minutos relógio | E24: 0 | F24: =IF(C24="","",IF(OR(COUNTIF($C:$C,C24)>1,COUNTIF(Prensa!C:C,C24)+COUNTIF(Carga!C:C,C24)+COUNTIF(Escolha41!C:C,C24)+COUNTIF(Escolha43!C:C,C24)-COUNTIF($C:$C,C24)>0),"CONFLITO","OK")) -> OK
A25: horRelogio | B25: CHANNEL | C25: D322 | D25: Horas relógio | E25: 0 | F25: =IF(C25="","",IF(OR(COUNTIF($C:$C,C25)>1,COUNTIF(Prensa!C:C,C25)+COUNTIF(Carga!C:C,C25)+COUNTIF(Escolha41!C:C,C25)+COUNTIF(Escolha43!C:C,C25)-COUNTIF($C:$C,C25)>0),"CONFLITO","OK")) -> OK
... A35: enviaRelogio | B35: BOOL | C35: H12.00 | D35: envia relogio | E35: 0 | F35: =IF(C35="","",IF(OR(COUNTIF($C:$C,C35)>1,COUNTIF(Prensa!C:C,C35)+COUNTIF(Carga!C:C,C35)+COUNTIF(Escolha41!C:C,C35)+COUNTIF(Escolha43!C:C,C35)-COUNTIF($C:$C,C35)>0),"CONFLITO","OK")) -> OK

Sheet Escolha43
A1: bit2 | B1: BOOL | E1: 0 | H1: bit2 | I1: BOOL | L1: 0
A2: d400D400 | B2: CHANNEL | E2: 0 | F2: =IF(OR(COUNTIF(C:C,C2)>1,COUNTIF(Prensa!C:C,C2)>0,COUNTIF(Carga!C:C,C2)>0,COUNTIF(Escolha41!C:C,C2)>0),"CONFLITO","OK") -> CONFLITO | H2: d400D400 | I2: CHANNEL | L2: 0
A3: caco | B3: BOOL | C3: 5.00 | D3: caco | E3: 0 | F3: =IF(OR(COUNTIF(C:C,C3)>1,COUNTIF(Prensa!C:C,C3)>0,COUNTIF(Carga!C:C,C3)>0,COUNTIF(Escolha41!C:C,C3)>0),"CONFLITO","OK") -> OK | H3: caco | I3: BOOL | J3: 0.00 | K3: caco | L3: 0
A4: box1 | B4: BOOL | C4: 5.01 | D4: box1 | E4: 0 | F4: =IF(OR(COUNTIF(C:C,C4)>1,COUNTIF(Prensa!C:C,C4)>0,COUNTIF(Carga!C:C,C4)>0,COUNTIF(Escolha41!C:C,C4)>0),"CONFLITO","OK") -> OK | H4: box1 | I4: BOOL | J4: 0.01 | K4: box1 | L4: 0
A5: box2 | B5: BOOL | C5: 5.02 | D5: box2 | E5: 0 | F5: =IF(OR(COUNTIF(C:C,C5)>1,COUNTIF(Prensa!C:C,C5)>0,COUNTIF(Carga!C:C,C5)>0,COUNTIF(Escolha41!C:C,C5)>0),"CONFLITO","OK") -> OK | H5: box2 | I5: BOOL | J5: 0.02 | K5: box2 | L5: 0
A6: box3 | B6: BOOL | C6: 5.03 | D6: box3 | E6: 0 | F6: =IF(OR(COUNTIF(C:C,C6)>1,COUNTIF(Prensa!C:C,C6)>0,COUNTIF(Carga!C:C,C6)>0,COUNTIF(Escolha41!C:C,C6)>0),"CONFLITO","OK") -> OK | H6: box3 | I6: BOOL | J6: 0.03 | K6: box3 | L6: 0
A7: box4 | B7: BOOL | C7: 5.04 | D7: box4 | E7: 0 | F7: =IF(OR(COUNTIF(C:C,C7)>1,COUNTIF(Prensa!C:C,C7)>0,COUNTIF(Carga!C:C,C7)>0,COUNTIF(Escolha41!C:C,C7)>0),"CONFLITO","OK") -> OK | H7: box4 | I7: BOOL | J7: 0.04 | K7: box4 | L7: 0
A8: box5 | B8: BOOL | C8: 5.05 | D8: box5 | E8: 0 | F8: =IF(OR(COUNTIF(C:C,C8)>1,COUNTIF(Prensa!C:C,C8)>0,COUNTIF(Carga!C:C,C8)>0,COUNTIF(Escolha41!C:C,C8)>0),"CONFLITO","OK") -> OK | H8: box5 | I8: BOOL | J8: 0.05 | K8: box5 | L8: 0
A9: box6 | B9: BOOL | C9: 5.06 | D9: box6 | E9: 0 | F9: =IF(OR(COUNTIF(C:C,C9)>1,COUNTIF(Prensa!C:C,C9)>0,COUNTIF(Carga!C:C,C9)>0,COUNTIF(Escolha41!C:C,C9)>0),"CONFLITO","OK") -> OK | H9: box6 | I9: BOOL | J9: 0.06 | K9: box6 | L9: 0
A10: resetCnt | B10: BOOL | C10: 5.07 | D10: reset contagem | E10: 0 | F10: =IF(OR(COUNTIF(C:C,C10)>1,COUNTIF(Prensa!C:C,C10)>0,COUNTIF(Carga!C:C,C10)>0,COUNTIF(Escolha41!C:C,C10)>0),"CONFLITO","OK") -> OK | H10: resetCnt | I10: BOOL | J10: 0.07 | K10: reset contagem | L10: 0
A11: totalPc | B11: BOOL | C11: 5.08 | D11: total peças | E11: 0 | F11: =IF(OR(COUNTIF(C:C,C11)>1,COUNTIF(Prensa!C:C,C11)>0,COUNTIF(Carga!C:C,C11)>0,COUNTIF(Escolha41!C:C,C11)>0),"CONFLITO","OK") -> OK | H11: totalPc | I11: BOOL | J11: 0.08 | K11: total peças | L11: 0
A12: selecaoCom | B12: BOOL | C12: 5.09 | D12: seleção comercial | E12: 0 | F12: =IF(OR(COUNTIF(C:C,C12)>1,COUNTIF(Prensa!C:C,C12)>0,COUNTIF(Carga!C:C,C12)>0,COUNTIF(Escolha41!C:C,C12)>0),"CONFLITO","OK") -> OK | H12: selecaoCom | I12: BOOL | J12: 0.09 | K12: seleção comercial | L12: 0
A13: TIM | B13: BOOL | C13: 5.12 | E13: 0 | F13: =IF(OR(COUNTIF(C:C,C13)>1,COUNTIF(Prensa!C:C,C13)>0,COUNTIF(Carga!C:C,C13)>0,COUNTIF(Escolha41!C:C,C13)>0),"CONFLITO","OK") -> OK | H13: TIM | I13: BOOL | J13: 0.12 | L13: 0
A14: cntBox0 | B14: CHANNEL | C14: D400 | D14: contagem box 0 | E14: 0 | F14: =IF(OR(COUNTIF(C:C,C14)>1,COUNTIF(Prensa!C:C,C14)>0,COUNTIF(Carga!C:C,C14)>0,COUNTIF(Escolha41!C:C,C14)>0),"CONFLITO","OK") -> OK | H14: cntBox0 | I14: CHANNEL | J14: D0 | K14: contagem box 0 | L14: 0
A15: cntBox1 | B15: CHANNEL | C15: D402 | D15: contagem box 1 | E15: 0 | F15: =IF(OR(COUNTIF(C:C,C15)>1,COUNTIF(Prensa!C:C,C15)>0,COUNTIF(Carga!C:C,C15)>0,COUNTIF(Escolha41!C:C,C15)>0),"CONFLITO","OK") -> OK | H15: cntBox1 | I15: CHANNEL | J15: D2 | K15: contagem box 1 | L15: 0
A16: cntBox2 | B16: CHANNEL | C16: D404 | D16: contagem box 2 | E16: 0 | F16: =IF(OR(COUNTIF(C:C,C16)>1,COUNTIF(Prensa!C:C,C16)>0,COUNTIF(Carga!C:C,C16)>0,COUNTIF(Escolha41!C:C,C16)>0),"CONFLITO","OK") -> OK | H16: cntBox2 | I16: CHANNEL | J16: D4 | K16: contagem box 2 | L16: 0
A17: cntBox3 | B17: CHANNEL | C17: D406 | D17: contagem box 3 | E17: 0 | F17: =IF(OR(COUNTIF(C:C,C17)>1,COUNTIF(Prensa!C:C,C17)>0,COUNTIF(Carga!C:C,C17)>0,COUNTIF(Escolha41!C:C,C17)>0),"CONFLITO","OK") -> OK | H17: cntBox3 | I17: CHANNEL | J17: D6 | K17: contagem box 3 | L17: 0
A18: cntBox4 | B18: CHANNEL | C18: D408 | D18: contagem box 4 | E18: 0 | F18: =IF(OR(COUNTIF(C:C,C18)>1,COUNTIF(Prensa!C:C,C18)>0,COUNTIF(Carga!C:C,C18)>0,COUNTIF(Escolha41!C:C,C18)>0),"CONFLITO","OK") -> OK | H18: cntBox4 | I18: CHANNEL | J18: D8 | K18: contagem box 4 | L18: 0
A19: cntBox5 | B19: CHANNEL | C19: D410 | D19: contagem box 5 | E19: 0 | F19: =IF(OR(COUNTIF(C:C,C19)>1,COUNTIF(Prensa!C:C,C19)>0,COUNTIF(Carga!C:C,C19)>0,COUNTIF(Escolha41!C:C,C19)>0),"CONFLITO","OK") -> OK | H19: cntBox5 | I19: CHANNEL | J19: D10 | K19: contagem box 5 | L19: 0
A20: cntBox6 | B20: CHANNEL | C20: D412 | D20: contagem box 6 | E20: 0 | F20: =IF(OR(COUNTIF(C:C,C20)>1,COUNTIF(Prensa!C:C,C20)>0,COUNTIF(Carga!C:C,C20)>0,COUNTIF(Escolha41!C:C,C20)>0),"CONFLITO","OK") -> OK | H20: cntBox6 | I20: CHANNEL | J20: D12 | K20: contagem box 6 | L20: 0
A21: cntTotal | B21: CHANNEL | C21: D414 | D21: contagem total | E21: 0 | F21: =IF(OR(COUNTIF(C:C,C21)>1,COUNTIF(Prensa!C:C,C21)>0,COUNTIF(Carga!C:C,C21)>0,COUNTIF(Escolha41!C:C,C21)>0),"CONFLITO","OK") -> OK | H21: cntTotal | I21: CHANNEL | J21: D14 | K21: contagem total | L21: 0
A22: cntAmostragem | B22: CHANNEL | C22: D416 | D22: contador amostragem | E22: 0 | F22: =IF(OR(COUNTIF(C:C,C22)>1,COUNTIF(Prensa!C:C,C22)>0,COUNTIF(Carga!C:C,C22)>0,COUNTIF(Escolha41!C:C,C22)>0),"CONFLITO","OK") -> OK | H22: cntAmostragem | I22: CHANNEL | J22: D18 | K22: contador amostragem | L22: 0
A23: segRelogio | B23: CHANNEL | C23: D418 | D23: Segundos Relógio | E23: 0 | F23: =IF(OR(COUNTIF(C:C,C23)>1,COUNTIF(Prensa!C:C,C23)>0,COUNTIF(Carga!C:C,C23)>0,COUNTIF(Escolha41!C:C,C23)>0),"CONFLITO","OK") -> OK | H23: segRelogio | I23: CHANNEL | J23: D630 | K23: Segundos Relógio | L23: 0
A24: minRelogio | B24: CHANNEL | C24: D420 | D24: Minutos relógio | E24: 0 | F24: =IF(OR(COUNTIF(C:C,C24)>1,COUNTIF(Prensa!C:C,C24)>0,COUNTIF(Carga!C:C,C24)>0,COUNTIF(Escolha41!C:C,C24)>0),"CONFLITO","OK") -> OK | H24: minRelogio | I24: CHANNEL | J24: D631 | K24: Minutos relógio | L24: 0
A25: horRelogio | B25: CHANNEL | C25: D422 | D25: Horas relógio | E25: 0 | F25: =IF(OR(COUNTIF(C:C,C25)>1,COUNTIF(Prensa!C:C,C25)>0,COUNTIF(Carga!C:C,C25)>0,COUNTIF(Escolha41!C:C,C25)>0),"CONFLITO","OK") -> OK | H25: horRelogio | I25: CHANNEL | J25: D632 | K25: Horas relógio | L25: 0
... A36: enviaRelogio | B36: BOOL | C36: H13.01 | D36: envia relogio | E36: 0 | F36: =IF(OR(COUNTIF(C:C,C36)>1,COUNTIF(Prensa!C:C,C36)>0,COUNTIF(Carga!C:C,C36)>0,COUNTIF(Escolha41!C:C,C36)>0),"CONFLITO","OK") -> OK | H36: enviaRelogio | I36: BOOL | J36: H10.01 | K36: envia relogio | L36: 0

Sheet SharedAddresses
A1: d0 à d99 | B1: prensa
A2: d100 à d199 | B2: carga
A3: d200 à d299 | B3: escolha 41
A4: d300 à d399 | B4: escolha 43

Sheet base
B1: BATIDAS | D1: TIME
A2: PH 29 | B2: T1 | C2: D308
A3: PH 30 | B3: T1 | C3: D309 | H3: D | I3: Conteúdo
A4: PH 31 | B4: T1 | C4: D310 | H4: D3001 | I4: Ano (2026)
A5: SEC 25 | B5: T1 | C5: D311 | H5: D3002 | I5: Mês (03)
A6: SEC 26 | B6: T1 | C6: D312 | H6: D3003 | I6: Dia (19)
A7: SEC 33 | B7: T1 | C7: D313 | H7: D3004 | I7: Hora
A8: PONTEIRO INICIO | C8: D298 | H8: D3005 | I8: Minuto
A9: TURNO | C9: D318 | H9: D3006 | I9: Segundo
F11: DATA | G11: D301 | H11: D302 | I11: D303 | J11: D304 | K11: D305 | L11: D306
F12: TURNO | G12: D318
F13: PRODUÇÃO | G13: D300 | H13: D301 | I13: D302 | J13: D303 | K13: D304 | L13: D305
F15: PONTEIRO | G15: DATA | H15: TURNO | I15: PRODUCAO
F16: D300 | G16: D301 ...D306 | H16: D307 | I16: D308 ... D313
F17: D3001 | G17: D3001...D3006 | H17: D3007 | I17: D3008...D3007
A23: ano_bd | B23: CHANNEL | C23: D301 | D23: ano bd | E23: 0
A24: mes_bd | B24: CHANNEL | C24: D302 | D24: mes bd | E24: 0
A25: dia_bd | B25: CHANNEL | C25: D303 | D25: dia bd | E25: 0
A26: hora_bd | B26: CHANNEL | C26: D304 | D26: hora bd | E26: 0
A27: min_bd | B27: CHANNEL | C27: D305 | D27: minuto bd | E27: 0
A28: ano_2dig | B28: CHANNEL | C28: D306 | D28: ano 2 dig | E28: 0
A29: seg_bd | B29: CHANNEL | C29: D307 | D29: seg bd | E29: 0
A30: HORA_DIA_CLP | B30: CHANNEL | C30: A352 | D30: hora e dia clp | E30: 0
A31: MES_ANO_CLP | B31: CHANNEL | C31: A353 | D31: mes e ano clp | E31: 0
A32: MIN_SEG_CLP | B32: CHANNEL | C32: A351 | D32: minuto e segundo clp | E32: 0

Sheet Planilha1
